2023-07-11 21:39:28,999 : INFO : root : Loading config.
2023-07-11 21:39:29,002 : INFO : YamlMultifileConfigLoader : Machine config file #1: config.yaml
2023-07-11 21:39:29,002 : INFO : ConfigProcessor : Loading config from cache: C:\Users\warzz\AppData\Local\Temp\c7ddc35c564c409ccec16ce42249e5f8.mpf_cache
2023-07-11 21:39:29,072 : INFO : ConfigProcessor : Loading config from cache: C:\Users\warzz\AppData\Local\Temp\b77c3901e90ec7d7cc601651512a0021.mpf_cache
2023-07-11 21:39:29,072 : INFO : ConfigProcessor : Loading config from cache: C:\Users\warzz\AppData\Local\Temp\a5b2fce8b210d64acc95275c2c9a2339.mpf_cache
2023-07-11 21:39:29,073 : INFO : Machine : Mission Pinball Framework Core Engine v0.56.0
2023-07-11 21:39:29,073 : INFO : Machine : Command line arguments: {'no_load_cache': False, 'create_config_cache': True, 'bcp': False, 'configfile': ['config.yaml'], 'force_assets_load': False, 'jsonlogging': False, 'logfile': 'logs\\2023-07-11-21-39-28-mpf-DESKTOP-VQ7DOMB.log', 'pause': False, 'production': False, 'text_ui': True, 'loglevel': 15, 'consoleloglevel': 20, 'force_platform': None, 'syslog_address': None, 'mc_file_name': None, 'no_sound': False}
2023-07-11 21:39:29,073 : INFO : Machine : MPF path: C:\Users\warzz\AppData\Local\Programs\Python\Python39\lib\site-packages\mpf
2023-07-11 21:39:29,073 : INFO : Machine : Machine path: d:\MPF\springbreak
2023-07-11 21:39:29,073 : INFO : Machine : Platform: win32
2023-07-11 21:39:29,073 : INFO : Machine : Python executable location: C:\Users\warzz\AppData\Local\Programs\Python\Python39\python.exe
2023-07-11 21:39:29,073 : INFO : Machine : Python version: 3.9.13 (64-bit)
2023-07-11 21:39:29,074 : INFO : Machine : Initialise MPF.
2023-07-11 21:39:29,206 : INFO : OPP : Connecting to /dev/ttyACM0 at 115200bps
2023-07-11 21:39:29,206 : INFO : Machine : Shutting down...
2023-07-11 21:39:29,207 : INFO : EventManager : Event: ======'shutdown'====== Args={}
2023-07-11 21:39:29,207 : ERROR : Machine : Failed to initialise MPF
Traceback (most recent call last):
  File "C:\Users\warzz\AppData\Local\Programs\Python\Python39\lib\site-packages\mpf\core\machine.py", line 679, in initialise_mpf
    raise init.exception()
  File "C:\Users\warzz\AppData\Local\Programs\Python\Python39\lib\site-packages\mpf\core\machine.py", line 246, in initialise
    await self.initialise_core_and_hardware()
  File "C:\Users\warzz\AppData\Local\Programs\Python\Python39\lib\site-packages\mpf\core\machine.py", line 242, in initialise_core_and_hardware
    await self._initialize_platforms()
  File "C:\Users\warzz\AppData\Local\Programs\Python\Python39\lib\site-packages\mpf\core\machine.py", line 333, in _initialize_platforms
    result.result()
  File "C:\Users\warzz\AppData\Local\Programs\Python\Python39\lib\site-packages\mpf\platforms\opp\opp.py", line 107, in initialize
    await self._connect_to_hardware()
  File "C:\Users\warzz\AppData\Local\Programs\Python\Python39\lib\site-packages\mpf\platforms\opp\opp.py", line 308, in _connect_to_hardware
    await comm.connect()
  File "C:\Users\warzz\AppData\Local\Programs\Python\Python39\lib\site-packages\mpf\platforms\base_serial_communicator.py", line 47, in connect
    await self._connect_to_hardware(self.port, self.baud, self.xonxoff)
  File "C:\Users\warzz\AppData\Local\Programs\Python\Python39\lib\site-packages\mpf\platforms\base_serial_communicator.py", line 56, in _connect_to_hardware
    self.reader, self.writer = await connector
  File "C:\Users\warzz\AppData\Local\Programs\Python\Python39\lib\site-packages\mpf\core\clock.py", line 152, in open_serial_connection
    transport, _ = await create_serial_connection(
  File "C:\Users\warzz\AppData\Local\Programs\Python\Python39\lib\asyncio\coroutines.py", line 124, in coro
    res = func(*args, **kw)
  File "C:\Users\warzz\AppData\Local\Programs\Python\Python39\lib\site-packages\serial_asyncio\__init__.py", line 410, in create_serial_connection
    ser = serial.serial_for_url(*args, **kwargs)
  File "C:\Users\warzz\AppData\Local\Programs\Python\Python39\lib\site-packages\serial\__init__.py", line 90, in serial_for_url
    instance.open()
  File "C:\Users\warzz\AppData\Local\Programs\Python\Python39\lib\site-packages\serial\serialwin32.py", line 64, in open
    raise SerialException("could not open port {!r}: {!r}".format(self.portstr, ctypes.WinError()))
serial.serialutil.SerialException: could not open port '/dev/ttyACM0': FileNotFoundError(2, 'A rendszer nem találja a megadott elérési utat.', None, 3)
2023-07-11 21:40:06,631 : INFO : root : MPF run loop ended.
